2021-11-07 00:55:02,884 INFO    MainThread:41817 [wandb_setup.py:_flush():71] setting env: {}
2021-11-07 00:55:02,884 INFO    MainThread:41817 [wandb_setup.py:_flush():71] setting login settings: {}
2021-11-07 00:55:02,884 INFO    MainThread:41817 [wandb_setup.py:_flush():71] setting login settings: {'mode': 'offline'}
2021-11-07 00:55:02,885 INFO    MainThread:41817 [wandb_init.py:_log_setup():357] Logging user logs to /home/cx/rmvision/yolov5-RM/wandb/offline-run-20211107_005502-12snnij8/logs/debug.log
2021-11-07 00:55:02,885 INFO    MainThread:41817 [wandb_init.py:_log_setup():358] Logging internal logs to /home/cx/rmvision/yolov5-RM/wandb/offline-run-20211107_005502-12snnij8/logs/debug-internal.log
2021-11-07 00:55:02,885 INFO    MainThread:41817 [wandb_init.py:init():390] calling init triggers
2021-11-07 00:55:02,885 INFO    MainThread:41817 [wandb_init.py:init():395] wandb.init called with sweep_config: {}
config: {'weights': 'best.pt', 'cfg': 'models/yolov5n.yaml', 'data': 'data/rm.yaml', 'hyp': {'lr0': 0.01, 'lrf': 0.2, 'momentum': 0.937, 'weight_decay': 0.0005, 'warmup_epochs': 3.0, 'warmup_momentum': 0.8, 'warmup_bias_lr': 0.1, 'box': 0.05, 'cls': 0.5, 'landmark': 0.005, 'cls_pw': 1.0, 'obj': 1.0, 'obj_pw': 1.0, 'iou_t': 0.2, 'anchor_t': 4.0, 'fl_gamma': 0.0, 'hsv_h': 0.015, 'hsv_s': 0.7, 'hsv_v': 0.4, 'degrees': 0.0, 'translate': 0.1, 'scale': 0.5, 'shear': 0.5, 'perspective': 0.0, 'flipud': 0.0, 'fliplr': 0.5, 'mosaic': 0.5, 'mixup': 0.0}, 'epochs': 300, 'batch_size': 16, 'img_size': [640, 640], 'rect': False, 'resume': False, 'nosave': False, 'notest': False, 'noautoanchor': False, 'evolve': False, 'bucket': '', 'cache_images': False, 'image_weights': False, 'device': '', 'multi_scale': False, 'single_cls': False, 'adam': False, 'sync_bn': False, 'local_rank': -1, 'log_imgs': 16, 'log_artifacts': False, 'workers': 4, 'project': 'runs/train', 'name': 'exp', 'exist_ok': False, 'total_batch_size': 16, 'world_size': 1, 'global_rank': -1, 'save_dir': 'runs/train/exp67'}
2021-11-07 00:55:02,885 INFO    MainThread:41817 [wandb_init.py:init():435] starting backend
2021-11-07 00:55:02,885 INFO    MainThread:41817 [backend.py:_multiprocessing_setup():95] multiprocessing start_methods=fork,spawn,forkserver, using: spawn
2021-11-07 00:55:02,903 INFO    MainThread:41817 [backend.py:ensure_launched():199] starting backend process...
2021-11-07 00:55:02,917 INFO    MainThread:41817 [backend.py:ensure_launched():204] started backend process with pid: 41853
2021-11-07 00:55:02,917 INFO    MainThread:41817 [wandb_init.py:init():444] backend started and connected
2021-11-07 00:55:02,921 INFO    MainThread:41817 [wandb_init.py:init():503] updated telemetry
2021-11-07 00:55:02,924 INFO    MainThread:41817 [wandb_init.py:init():576] starting run threads in backend
2021-11-07 00:55:04,186 INFO    MainThread:41817 [wandb_run.py:_console_start():1693] atexit reg
2021-11-07 00:55:04,186 INFO    MainThread:41817 [wandb_run.py:_redirect():1567] redirect: SettingsConsole.REDIRECT
2021-11-07 00:55:04,186 INFO    MainThread:41817 [wandb_run.py:_redirect():1572] Redirecting console.
2021-11-07 00:55:04,187 INFO    MainThread:41817 [wandb_run.py:_redirect():1628] Redirects installed.
2021-11-07 00:55:04,187 INFO    MainThread:41817 [wandb_init.py:init():603] run started, returning control to user process
2021-11-07 00:55:04,433 INFO    MainThread:41817 [wandb_run.py:_atexit_cleanup():1663] got exitcode: 1
2021-11-07 00:55:04,433 INFO    MainThread:41817 [wandb_run.py:_restore():1635] restore
2021-11-07 00:55:04,477 INFO    MainThread:41817 [wandb_run.py:_restore():1635] restore
2021-11-07 00:55:06,742 ERROR   MainThread:41817 [wandb_run.py:_atexit_cleanup():1681] Problem finishing run
Traceback (most recent call last):
  File "/home/cx/miniconda3/envs/ml/lib/python3.8/site-packages/wandb/sdk/wandb_run.py", line 1671, in _atexit_cleanup
    self._on_finish()
  File "/home/cx/miniconda3/envs/ml/lib/python3.8/site-packages/wandb/sdk/wandb_run.py", line 1817, in _on_finish
    self._console_stop()  # TODO: there's a race here with jupyter console logging
  File "/home/cx/miniconda3/envs/ml/lib/python3.8/site-packages/wandb/sdk/wandb_run.py", line 1711, in _console_stop
    self._restore()
  File "/home/cx/miniconda3/envs/ml/lib/python3.8/site-packages/wandb/sdk/wandb_run.py", line 1639, in _restore
    self._out_redir.uninstall()
  File "/home/cx/miniconda3/envs/ml/lib/python3.8/site-packages/wandb/sdk/lib/redirect.py", line 733, in uninstall
    time.sleep(1)
  File "/home/cx/miniconda3/envs/ml/lib/python3.8/site-packages/torch/utils/data/_utils/signal_handling.py", line 66, in handler
    _error_if_any_worker_fails()
RuntimeError: DataLoader worker (pid 41941) exited unexpectedly with exit code 1. Details are lost due to multiprocessing. Rerunning with num_workers=0 may give better error trace.
