2021-11-07 00:33:49,190 INFO    MainThread:40390 [internal.py:wandb_internal():87] W&B internal server running at pid: 40390, started at: 2021-11-07 00:33:49.190514
2021-11-07 00:33:49,192 DEBUG   HandlerThread:40390 [handler.py:handle_request():130] handle_request: run_start
2021-11-07 00:33:49,192 INFO    WriterThread:40390 [datastore.py:open_for_write():77] open: /home/cx/rmvision/yolov5-RM/wandb/offline-run-20211107_003348-12snnij8/run-12snnij8.wandb
2021-11-07 00:33:49,193 DEBUG   HandlerThread:40390 [meta.py:__init__():40] meta init
2021-11-07 00:33:49,193 DEBUG   HandlerThread:40390 [meta.py:__init__():54] meta init done
2021-11-07 00:33:49,193 DEBUG   HandlerThread:40390 [meta.py:probe():214] probe
2021-11-07 00:33:49,199 DEBUG   HandlerThread:40390 [git.py:repo():33] git repository is invalid
2021-11-07 00:33:49,199 DEBUG   HandlerThread:40390 [meta.py:_save_pip():58] save pip
2021-11-07 00:33:49,199 DEBUG   HandlerThread:40390 [meta.py:_save_pip():72] save pip done
2021-11-07 00:33:49,199 DEBUG   HandlerThread:40390 [meta.py:_save_conda():79] save conda
2021-11-07 00:33:50,142 DEBUG   HandlerThread:40390 [meta.py:_save_conda():89] save conda done
2021-11-07 00:33:50,142 DEBUG   HandlerThread:40390 [meta.py:probe():252] probe done
2021-11-07 00:33:55,257 WARNING MainThread:40390 [internal.py:wandb_internal():146] Internal process interrupt: 1
2021-11-07 00:41:02,708 WARNING MainThread:40390 [internal.py:is_dead():366] Internal process exiting, parent pid 40355 disappeared
2021-11-07 00:41:02,708 ERROR   MainThread:40390 [internal.py:wandb_internal():142] Internal process shutdown.
2021-11-07 00:41:03,014 INFO    WriterThread:40390 [datastore.py:close():281] close: /home/cx/rmvision/yolov5-RM/wandb/offline-run-20211107_003348-12snnij8/run-12snnij8.wandb
2021-11-07 00:41:03,023 INFO    HandlerThread:40390 [handler.py:finish():731] shutting down handler
2021-11-07 00:41:03,281 INFO    SenderThread:40390 [sender.py:finish():1091] shutting down sender
2021-11-07 00:41:03,282 INFO    MainThread:40390 [internal.py:handle_exit():77] Internal process exited
