Scanning '/home/cx/rmvision/datasets/final/train/labels.cache' for images and labels... 180 found, 0 missing, 0 empty, 0 corrupted: 100%|███████████████████████████████████████████████████████████████████████████████████████████████████████████████| 180/180 [00:00<?, ?it/s]
Scanning '/home/cx/rmvision/datasets/final/val/labels.cache' for images and labels... 20 found, 0 missing, 0 empty, 0 corrupted: 100%|████████████████████████████████████████████████████████████████████████████████████████████████████████████████████| 20/20 [00:00<?, ?it/s]
None
Traceback (most recent call last):
  File "train.py", line 515, in <module>
    train(hyp, opt, device, tb_writer, wandb)
  File "train.py", line 200, in train
    testloader = create_dataloader(test_path, imgsz_test, total_batch_size, gs, opt,  # testloader
  File "/home/cx/rmvision/yolov5-RM/utils/face_datasets.py", line 78, in create_dataloader
    dataloader = loader(dataset,
  File "/home/cx/rmvision/yolov5-RM/utils/face_datasets.py", line 94, in __init__
    self.iterator = super().__iter__()
  File "/home/cx/miniconda3/envs/ml/lib/python3.8/site-packages/torch/utils/data/dataloader.py", line 359, in __iter__
    return self._get_iterator()
  File "/home/cx/miniconda3/envs/ml/lib/python3.8/site-packages/torch/utils/data/dataloader.py", line 305, in _get_iterator
    return _MultiProcessingDataLoaderIter(self)
  File "/home/cx/miniconda3/envs/ml/lib/python3.8/site-packages/torch/utils/data/dataloader.py", line 944, in __init__
    self._reset(loader, first_iter=True)
  File "/home/cx/miniconda3/envs/ml/lib/python3.8/site-packages/torch/utils/data/dataloader.py", line 975, in _reset
    self._try_put_index()
  File "/home/cx/miniconda3/envs/ml/lib/python3.8/site-packages/torch/utils/data/dataloader.py", line 1220, in _try_put_index
    self._index_queues[worker_queue_idx].put((self._send_idx, index))
  File "/home/cx/miniconda3/envs/ml/lib/python3.8/multiprocessing/queues.py", line 88, in put
    self._start_thread()
  File "/home/cx/miniconda3/envs/ml/lib/python3.8/multiprocessing/queues.py", line 173, in _start_thread
    self._thread.start()
  File "/home/cx/miniconda3/envs/ml/lib/python3.8/threading.py", line 857, in start
    self._started.wait()
  File "/home/cx/miniconda3/envs/ml/lib/python3.8/threading.py", line 558, in wait
    signaled = self._cond.wait(timeout)
  File "/home/cx/miniconda3/envs/ml/lib/python3.8/threading.py", line 302, in wait
    waiter.acquire()
  File "/home/cx/miniconda3/envs/ml/lib/python3.8/site-packages/torch/utils/data/_utils/signal_handling.py", line 66, in handler
    _error_if_any_worker_fails()
RuntimeError: DataLoader worker (pid 41572) exited unexpectedly with exit code 1. Details are lost due to multiprocessing. Rerunning with num_workers=0 may give better error trace.
None
None
None
None
None
None